id: PYSEC-2019-133
package:
  name: urllib3
  ecosystem: PyPI
summary: Vulnerability in urllib3
details: The urllib3 library before 1.24.2 for Python mishandles certain cases where
  the desired set of CA certificates is different from the OS store of CA certificates,
  which results in SSL connections succeeding in situations where a verification failure
  is the correct outcome. This is related to use of the ssl_context, ca_certs, or
  ca_certs_dir argument.
affects:
  ranges:
  - type: ECOSYSTEM
    fixed: 1.24.2
references:
- type: WEB
  url: https://github.com/urllib3/urllib3/compare/a6ec68a...1efadf4
- type: WEB
  url: http://www.openwall.com/lists/oss-security/2019/04/19/1
- type: WEB
  url: https://usn.ubuntu.com/3990-1/
- type: WEB
  url: http://lists.opensuse.org/opensuse-security-announce/2019-09/msg00039.html
- type: WEB
  url: http://lists.opensuse.org/opensuse-security-announce/2019-09/msg00041.html
- type: WEB
  url: https://access.redhat.com/errata/RHSA-2019:3335
- type: WEB
  url: https://access.redhat.com/errata/RHSA-2019:3590
- type: WEB
  url: https://lists.fedoraproject.org/archives/list/package-announce@lists.fedoraproject.org/message/NKGPJLVLVYCL4L4B4G5TIOTVK4BKPG72/
- type: WEB
  url: https://lists.fedoraproject.org/archives/list/package-announce@lists.fedoraproject.org/message/XOSA2NT4DUQDBEIWE6O7KKD24XND7TE2/
aliases:
- CVE-2019-11324
modified: "2019-09-14T18:15:00Z"
published: "2019-04-18T21:29:00Z"
